Workbook

Sheet Sheet1
A1: 📊 OIL ANALYSIS – EQUIPMENT DIAGNOSTIC DASHBOARD
A2: Select equipment from the dropdown below — all readings, KPIs, and recommendations update automatically
A4: SELECT EQUIPMENT: | B4: R2.432.KB101(1) | F4: ⬆ Click the cell above and choose from the dropdown list to switch equipment
A6: Asset ID: | B6: {=XLOOKUP(B4,'Equipment Registry'!A2:A1016,'Equipment Registry'!C2:C1016)} -> 40104806 | C6: Description: | D6: {=IFERROR(INDEX('_lookup'!$C:$C,MATCH($B$4,'_lookup'!$A:$A,0)),"")} | G6: Manufacturer: | H6: {=IFERROR(INDEX('_lookup'!$D:$D,MATCH($B$4,'_lookup'!$A:$A,0)),"")} | J6: Model: | K6: {=IFERROR(INDEX('_lookup'!$E:$E,MATCH($B$4,'_lookup'!$A:$A,0)),"")} | M6: Lubricant: | N6: {=IFERROR(INDEX('_lookup'!$F:$F,MATCH($B$4,'_lookup'!$A:$A,0)),"")} | P6: Visc Type: | Q6: {=IFERROR(INDEX('_lookup'!$G:$G,MATCH($B$4,'_lookup'!$A:$A,0)),"")}
A8: Latest Date | C8: Latest Sample | E8: Overall Status | G8: Viscosity | I8: TAN | K8: Water (Vol%) | M8: Fe Iron (ppm) | O8: Cu Copper | Q8: Si Silicon
A9: {=IFERROR(INDEX('_lookup'!$I:$I,MATCH($B$4,'_lookup'!$A:$A,0)),"")} | C9: {=IFERROR(INDEX('_lookup'!$J:$J,MATCH($B$4,'_lookup'!$A:$A,0)),"")} | E9: {=IFERROR(INDEX('_lookup'!$H:$H,MATCH($B$4,'_lookup'!$A:$A,0)),"")} | G9: {=IFERROR(INDEX('_lookup'!$K:$K,MATCH($B$4,'_lookup'!$A:$A,0)),"")} | I9: {=IFERROR(INDEX('_lookup'!$L:$L,MATCH($B$4,'_lookup'!$A:$A,0)),"")} | K9: {=IFERROR(INDEX('_lookup'!$M:$M,MATCH($B$4,'_lookup'!$A:$A,0)),"")} | M9: {=IFERROR(INDEX('_lookup'!$N:$N,MATCH($B$4,'_lookup'!$A:$A,0)),"")} | O9: {=IFERROR(INDEX('_lookup'!$O:$O,MATCH($B$4,'_lookup'!$A:$A,0)),"")} | Q9: {=IFERROR(INDEX('_lookup'!$P:$P,MATCH($B$4,'_lookup'!$A:$A,0)),"")}
A12: Sample Date | B12: Sample ID | C12: Status | D12: Cont. Rating | E12: Equip. Rating | F12: Lub. Rating | G12: PQ Index | H12: Viscosity (cSt) | I12: TAN (mgKOH/g) | J12: Water (Vol%) | K12: Fe Iron (ppm) | L12: Cu Copper (ppm) | M12: Si Silicon (ppm) | N12: Al Alum. (ppm) | O12: P Phosph. (ppm) | P12: Oxidation (Ab/cm)
A13: {=IFERROR(INDEX('_samples'!$B:$B,SMALL(IF('_samples'!$A:$A=$B$4,ROW('_samples'!$A:$A)),1)),"")} | B13: {=IFERROR(INDEX('_samples'!$C:$C,SMALL(IF('_samples'!$A:$A=$B$4,ROW('_samples'!$A:$A)),1)),"")} | C13: {=IFERROR(INDEX('_samples'!$D:$D,SMALL(IF('_samples'!$A:$A=$B$4,ROW('_samples'!$A:$A)),1)),"")} | D13: {=IFERROR(INDEX('_samples'!$E:$E,SMALL(IF('_samples'!$A:$A=$B$4,ROW('_samples'!$A:$A)),1)),"")} | E13: {=IFERROR(INDEX('_samples'!$F:$F,SMALL(IF('_samples'!$A:$A=$B$4,ROW('_samples'!$A:$A)),1)),"")} | F13: {=IFERROR(INDEX('_samples'!$G:$G,SMALL(IF('_samples'!$A:$A=$B$4,ROW('_samples'!$A:$A)),1)),"")} | G13: {=IFERROR(INDEX('_samples'!$H:$H,SMALL(IF('_samples'!$A:$A=$B$4,ROW('_samples'!$A:$A)),1)),"")} | H13: {=IFERROR(INDEX('_samples'!$I:$I,SMALL(IF('_samples'!$A:$A=$B$4,ROW('_samples'!$A:$A)),1)),"")} | I13: {=IFERROR(INDEX('_samples'!$J:$J,SMALL(IF('_samples'!$A:$A=$B$4,ROW('_samples'!$A:$A)),1)),"")} | J13: {=IFERROR(INDEX('_samples'!$K:$K,SMALL(IF('_samples'!$A:$A=$B$4,ROW('_samples'!$A:$A)),1)),"")} | K13: {=IFERROR(INDEX('_samples'!$L:$L,SMALL(IF('_samples'!$A:$A=$B$4,ROW('_samples'!$A:$A)),1)),"")} | L13: {=IFERROR(INDEX('_samples'!$M:$M,SMALL(IF('_samples'!$A:$A=$B$4,ROW('_samples'!$A:$A)),1)),"")} | M13: {=IFERROR(INDEX('_samples'!$N:$N,SMALL(IF('_samples'!$A:$A=$B$4,ROW('_samples'!$A:$A)),1)),"")} | N13: {=IFERROR(INDEX('_samples'!$O:$O,SMALL(IF('_samples'!$A:$A=$B$4,ROW('_samples'!$A:$A)),1)),"")} | O13: {=IFERROR(INDEX('_samples'!$P:$P,SMALL(IF('_samples'!$A:$A=$B$4,ROW('_samples'!$A:$A)),1)),"")} | P13: {=IFERROR(INDEX('_samples'!$R:$R,SMALL(IF('_samples'!$A:$A=$B$4,ROW('_samples'!$A:$A)),1)),"")}
A14: {=IFERROR(INDEX('_samples'!$B:$B,SMALL(IF('_samples'!$A:$A=$B$4,ROW('_samples'!$A:$A)),2)),"")} | B14: {=IFERROR(INDEX('_samples'!$C:$C,SMALL(IF('_samples'!$A:$A=$B$4,ROW('_samples'!$A:$A)),2)),"")} | C14: {=IFERROR(INDEX('_samples'!$D:$D,SMALL(IF('_samples'!$A:$A=$B$4,ROW('_samples'!$A:$A)),2)),"")} | D14: {=IFERROR(INDEX('_samples'!$E:$E,SMALL(IF('_samples'!$A:$A=$B$4,ROW('_samples'!$A:$A)),2)),"")} | E14: {=IFERROR(INDEX('_samples'!$F:$F,SMALL(IF('_samples'!$A:$A=$B$4,ROW('_samples'!$A:$A)),2)),"")} | F14: {=IFERROR(INDEX('_samples'!$G:$G,SMALL(IF('_samples'!$A:$A=$B$4,ROW('_samples'!$A:$A)),2)),"")} | G14: {=IFERROR(INDEX('_samples'!$H:$H,SMALL(IF('_samples'!$A:$A=$B$4,ROW('_samples'!$A:$A)),2)),"")} | H14: {=IFERROR(INDEX('_samples'!$I:$I,SMALL(IF('_samples'!$A:$A=$B$4,ROW('_samples'!$A:$A)),2)),"")} | I14: {=IFERROR(INDEX('_samples'!$J:$J,SMALL(IF('_samples'!$A:$A=$B$4,ROW('_samples'!$A:$A)),2)),"")} | J14: {=IFERROR(INDEX('_samples'!$K:$K,SMALL(IF('_samples'!$A:$A=$B$4,ROW('_samples'!$A:$A)),2)),"")} | K14: {=IFERROR(INDEX('_samples'!$L:$L,SMALL(IF('_samples'!$A:$A=$B$4,ROW('_samples'!$A:$A)),2)),"")} | L14: {=IFERROR(INDEX('_samples'!$M:$M,SMALL(IF('_samples'!$A:$A=$B$4,ROW('_samples'!$A:$A)),2)),"")} | M14: {=IFERROR(INDEX('_samples'!$N:$N,SMALL(IF('_samples'!$A:$A=$B$4,ROW('_samples'!$A:$A)),2)),"")} | N14: {=IFERROR(INDEX('_samples'!$O:$O,SMALL(IF('_samples'!$A:$A=$B$4,ROW('_samples'!$A:$A)),2)),"")} | O14: {=IFERROR(INDEX('_samples'!$P:$P,SMALL(IF('_samples'!$A:$A=$B$4,ROW('_samples'!$A:$A)),2)),"")} | P14: {=IFERROR(INDEX('_samples'!$R:$R,SMALL(IF('_samples'!$A:$A=$B$4,ROW('_samples'!$A:$A)),2)),"")}
A15: {=IFERROR(INDEX('_samples'!$B:$B,SMALL(IF('_samples'!$A:$A=$B$4,ROW('_samples'!$A:$A)),3)),"")} | B15: {=IFERROR(INDEX('_samples'!$C:$C,SMALL(IF('_samples'!$A:$A=$B$4,ROW('_samples'!$A:$A)),3)),"")} | C15: {=IFERROR(INDEX('_samples'!$D:$D,SMALL(IF('_samples'!$A:$A=$B$4,ROW('_samples'!$A:$A)),3)),"")} | D15: {=IFERROR(INDEX('_samples'!$E:$E,SMALL(IF('_samples'!$A:$A=$B$4,ROW('_samples'!$A:$A)),3)),"")} | E15: {=IFERROR(INDEX('_samples'!$F:$F,SMALL(IF('_samples'!$A:$A=$B$4,ROW('_samples'!$A:$A)),3)),"")} | F15: {=IFERROR(INDEX('_samples'!$G:$G,SMALL(IF('_samples'!$A:$A=$B$4,ROW('_samples'!$A:$A)),3)),"")} | G15: {=IFERROR(INDEX('_samples'!$H:$H,SMALL(IF('_samples'!$A:$A=$B$4,ROW('_samples'!$A:$A)),3)),"")} | H15: {=IFERROR(INDEX('_samples'!$I:$I,SMALL(IF('_samples'!$A:$A=$B$4,ROW('_samples'!$A:$A)),3)),"")} | I15: {=IFERROR(INDEX('_samples'!$J:$J,SMALL(IF('_samples'!$A:$A=$B$4,ROW('_samples'!$A:$A)),3)),"")} | J15: {=IFERROR(INDEX('_samples'!$K:$K,SMALL(IF('_samples'!$A:$A=$B$4,ROW('_samples'!$A:$A)),3)),"")} | K15: {=IFERROR(INDEX('_samples'!$L:$L,SMALL(IF('_samples'!$A:$A=$B$4,ROW('_samples'!$A:$A)),3)),"")} | L15: {=IFERROR(INDEX('_samples'!$M:$M,SMALL(IF('_samples'!$A:$A=$B$4,ROW('_samples'!$A:$A)),3)),"")} | M15: {=IFERROR(INDEX('_samples'!$N:$N,SMALL(IF('_samples'!$A:$A=$B$4,ROW('_samples'!$A:$A)),3)),"")} | N15: {=IFERROR(INDEX('_samples'!$O:$O,SMALL(IF('_samples'!$A:$A=$B$4,ROW('_samples'!$A:$A)),3)),"")} | O15: {=IFERROR(INDEX('_samples'!$P:$P,SMALL(IF('_samples'!$A:$A=$B$4,ROW('_samples'!$A:$A)),3)),"")} | P15: {=IFERROR(INDEX('_samples'!$R:$R,SMALL(IF('_samples'!$A:$A=$B$4,ROW('_samples'!$A:$A)),3)),"")}
A16: {=IFERROR(INDEX('_samples'!$B:$B,SMALL(IF('_samples'!$A:$A=$B$4,ROW('_samples'!$A:$A)),4)),"")} | B16: {=IFERROR(INDEX('_samples'!$C:$C,SMALL(IF('_samples'!$A:$A=$B$4,ROW('_samples'!$A:$A)),4)),"")} | C16: {=IFERROR(INDEX('_samples'!$D:$D,SMALL(IF('_samples'!$A:$A=$B$4,ROW('_samples'!$A:$A)),4)),"")} | D16: {=IFERROR(INDEX('_samples'!$E:$E,SMALL(IF('_samples'!$A:$A=$B$4,ROW('_samples'!$A:$A)),4)),"")} | E16: {=IFERROR(INDEX('_samples'!$F:$F,SMALL(IF('_samples'!$A:$A=$B$4,ROW('_samples'!$A:$A)),4)),"")} | F16: {=IFERROR(INDEX('_samples'!$G:$G,SMALL(IF('_samples'!$A:$A=$B$4,ROW('_samples'!$A:$A)),4)),"")} | G16: {=IFERROR(INDEX('_samples'!$H:$H,SMALL(IF('_samples'!$A:$A=$B$4,ROW('_samples'!$A:$A)),4)),"")} | H16: {=IFERROR(INDEX('_samples'!$I:$I,SMALL(IF('_samples'!$A:$A=$B$4,ROW('_samples'!$A:$A)),4)),"")} | I16: {=IFERROR(INDEX('_samples'!$J:$J,SMALL(IF('_samples'!$A:$A=$B$4,ROW('_samples'!$A:$A)),4)),"")} | J16: {=IFERROR(INDEX('_samples'!$K:$K,SMALL(IF('_samples'!$A:$A=$B$4,ROW('_samples'!$A:$A)),4)),"")} | K16: {=IFERROR(INDEX('_samples'!$L:$L,SMALL(IF('_samples'!$A:$A=$B$4,ROW('_samples'!$A:$A)),4)),"")} | L16: {=IFERROR(INDEX('_samples'!$M:$M,SMALL(IF('_samples'!$A:$A=$B$4,ROW('_samples'!$A:$A)),4)),"")} | M16: {=IFERROR(INDEX('_samples'!$N:$N,SMALL(IF('_samples'!$A:$A=$B$4,ROW('_samples'!$A:$A)),4)),"")} | N16: {=IFERROR(INDEX('_samples'!$O:$O,SMALL(IF('_samples'!$A:$A=$B$4,ROW('_samples'!$A:$A)),4)),"")} | O16: {=IFERROR(INDEX('_samples'!$P:$P,SMALL(IF('_samples'!$A:$A=$B$4,ROW('_samples'!$A:$A)),4)),"")} | P16: {=IFERROR(INDEX('_samples'!$R:$R,SMALL(IF('_samples'!$A:$A=$B$4,ROW('_samples'!$A:$A)),4)),"")}
A17: {=IFERROR(INDEX('_samples'!$B:$B,SMALL(IF('_samples'!$A:$A=$B$4,ROW('_samples'!$A:$A)),5)),"")} | B17: {=IFERROR(INDEX('_samples'!$C:$C,SMALL(IF('_samples'!$A:$A=$B$4,ROW('_samples'!$A:$A)),5)),"")} | C17: {=IFERROR(INDEX('_samples'!$D:$D,SMALL(IF('_samples'!$A:$A=$B$4,ROW('_samples'!$A:$A)),5)),"")} | D17: {=IFERROR(INDEX('_samples'!$E:$E,SMALL(IF('_samples'!$A:$A=$B$4,ROW('_samples'!$A:$A)),5)),"")} | E17: {=IFERROR(INDEX('_samples'!$F:$F,SMALL(IF('_samples'!$A:$A=$B$4,ROW('_samples'!$A:$A)),5)),"")} | F17: {=IFERROR(INDEX('_samples'!$G:$G,SMALL(IF('_samples'!$A:$A=$B$4,ROW('_samples'!$A:$A)),5)),"")} | G17: {=IFERROR(INDEX('_samples'!$H:$H,SMALL(IF('_samples'!$A:$A=$B$4,ROW('_samples'!$A:$A)),5)),"")} | H17: {=IFERROR(INDEX('_samples'!$I:$I,SMALL(IF('_samples'!$A:$A=$B$4,ROW('_samples'!$A:$A)),5)),"")} | I17: {=IFERROR(INDEX('_samples'!$J:$J,SMALL(IF('_samples'!$A:$A=$B$4,ROW('_samples'!$A:$A)),5)),"")} | J17: {=IFERROR(INDEX('_samples'!$K:$K,SMALL(IF('_samples'!$A:$A=$B$4,ROW('_samples'!$A:$A)),5)),"")} | K17: {=IFERROR(INDEX('_samples'!$L:$L,SMALL(IF('_samples'!$A:$A=$B$4,ROW('_samples'!$A:$A)),5)),"")} | L17: {=IFERROR(INDEX('_samples'!$M:$M,SMALL(IF('_samples'!$A:$A=$B$4,ROW('_samples'!$A:$A)),5)),"")} | M17: {=IFERROR(INDEX('_samples'!$N:$N,SMALL(IF('_samples'!$A:$A=$B$4,ROW('_samples'!$A:$A)),5)),"")} | N17: {=IFERROR(INDEX('_samples'!$O:$O,SMALL(IF('_samples'!$A:$A=$B$4,ROW('_samples'!$A:$A)),5)),"")} | O17: {=IFERROR(INDEX('_samples'!$P:$P,SMALL(IF('_samples'!$A:$A=$B$4,ROW('_samples'!$A:$A)),5)),"")} | P17: {=IFERROR(INDEX('_samples'!$R:$R,SMALL(IF('_samples'!$A:$A=$B$4,ROW('_samples'!$A:$A)),5)),"")}
A19: 📌 ALERT THRESHOLDS & DIAGNOSTIC GUIDE
A20: Parameter | B20: Sample History (Last 5 — Oldest → Latest)
A21: Parameter | B21: =IFERROR(minifs('Data Entry_BD'!$D$6:$D$430,'Data Entry_BD'!$A$6:$A$430,$B$4,'Data Entry_BD'!$D$6:$D$430,">"&B21),"") -> #REF! | C21: =IFERROR(TEXT(W12,"dd-mmm-yy"),"—") -> 30-Dec-99 | D21: =IFERROR(TEXT(W13,"dd-mmm-yy"),"—") -> 30-Dec-99 | E21: =IFERROR(TEXT(T14,"dd-mmm-yy"),"—") -> 30-Dec-99 | F21: =IFERROR(TEXT(T15,"dd-mmm-yy"),"—") -> 30-Dec-99
A22: LUBRICANT
A23: Report Status | B23: {=IFERROR(INDEX('Data Entry_BD'!$E:$E,X11),"—")} -> #REF! | C23: {=IFERROR(INDEX('Data Entry_BD'!$E:$E,X12),"—")} -> #REF! | D23: {=IFERROR(INDEX('Data Entry_BD'!$E:$E,X13),"—")} -> #REF! | E23: {=IFERROR(INDEX('Data Entry_BD'!$E:$E,U14),"—")} -> #REF! | F23: {=IFERROR(INDEX('Data Entry_BD'!$E:$E,U15),"—")} -> #REF!
A24: Visc@40°C (cSt) | B24: {=IFERROR(INDEX('Data Entry_BD'!$M:$M,X11),"—")} -> #REF! | C24: {=IFERROR(INDEX('Data Entry_BD'!$M:$M,X12),"—")} -> #REF! | D24: {=IFERROR(INDEX('Data Entry_BD'!$M:$M,X13),"—")} -> #REF! | E24: {=IFERROR(INDEX('Data Entry_BD'!$M:$M,U14),"—")} -> #REF! | F24: {=IFERROR(INDEX('Data Entry_BD'!$M:$M,U15),"—")} -> #REF!
A25: Water (Vol%) | B25: {=IFERROR(INDEX('Data Entry_BD'!$P:$P,X11),"—")} -> #REF! | C25: {=IFERROR(INDEX('Data Entry_BD'!$P:$P,X12),"—")} -> #REF! | D25: {=IFERROR(INDEX('Data Entry_BD'!$P:$P,X13),"—")} -> #REF! | E25: {=IFERROR(INDEX('Data Entry_BD'!$P:$P,U14),"—")} -> #REF! | F25: {=IFERROR(INDEX('Data Entry_BD'!$P:$P,U15),"—")} -> #REF!
A26: WEAR (ppm)
A27: Fe (Iron) | B27: {=IFERROR(INDEX('Data Entry_BD'!$T:$T,X11),"—")} -> #REF! | C27: {=IFERROR(INDEX('Data Entry_BD'!$T:$T,X12),"—")} -> #REF! | D27: {=IFERROR(INDEX('Data Entry_BD'!$T:$T,X13),"—")} -> #REF! | E27: {=IFERROR(INDEX('Data Entry_BD'!$T:$T,U14),"—")} -> #REF! | F27: {=IFERROR(INDEX('Data Entry_BD'!$T:$T,U15),"—")} -> #REF!
A28: Al (Aluminum) | B28: {=IFERROR(INDEX('Data Entry_BD'!$U:$U,X11),"—")} -> #REF! | C28: {=IFERROR(INDEX('Data Entry_BD'!$U:$U,X12),"—")} -> #REF! | D28: {=IFERROR(INDEX('Data Entry_BD'!$U:$U,X13),"—")} -> #REF! | E28: {=IFERROR(INDEX('Data Entry_BD'!$U:$U,U14),"—")} -> #REF! | F28: {=IFERROR(INDEX('Data Entry_BD'!$U:$U,U15),"—")} -> #REF!
A29: Cu (Copper) | B29: {=IFERROR(INDEX('Data Entry_BD'!$V:$V,X11),"—")} -> #REF! | C29: {=IFERROR(INDEX('Data Entry_BD'!$V:$V,X12),"—")} -> #REF! | D29: {=IFERROR(INDEX('Data Entry_BD'!$V:$V,X13),"—")} -> #REF! | E29: {=IFERROR(INDEX('Data Entry_BD'!$V:$V,U14),"—")} -> #REF! | F29: {=IFERROR(INDEX('Data Entry_BD'!$V:$V,U15),"—")} -> #REF!
A30: Cr (Chromium) | B30: {=IFERROR(INDEX('Data Entry_BD'!$W:$W,X11),"—")} -> #REF! | C30: {=IFERROR(INDEX('Data Entry_BD'!$W:$W,X12),"—")} -> #REF! | D30: {=IFERROR(INDEX('Data Entry_BD'!$W:$W,X13),"—")} -> #REF! | E30: {=IFERROR(INDEX('Data Entry_BD'!$W:$W,U14),"—")} -> #REF! | F30: {=IFERROR(INDEX('Data Entry_BD'!$W:$W,U15),"—")} -> #REF!
A31: CONTAM (ppm)
A32: Si (Silicon) | B32: {=IFERROR(INDEX('Data Entry_BD'!$Z:$Z,X11),"—")} -> #REF! | C32: {=IFERROR(INDEX('Data Entry_BD'!$Z:$Z,X12),"—")} -> #REF! | D32: {=IFERROR(INDEX('Data Entry_BD'!$Z:$Z,X13),"—")} -> #REF! | E32: {=IFERROR(INDEX('Data Entry_BD'!$Z:$Z,U14),"—")} -> #REF! | F32: {=IFERROR(INDEX('Data Entry_BD'!$Z:$Z,U15),"—")} -> #REF!
A33: Na (Sodium) | B33: {=IFERROR(INDEX('Data Entry_BD'!$AA:$AA,X11),"—")} -> #REF! | C33: {=IFERROR(INDEX('Data Entry_BD'!$AA:$AA,X12),"—")} -> #REF! | D33: {=IFERROR(INDEX('Data Entry_BD'!$AA:$AA,X13),"—")} -> #REF! | E33: {=IFERROR(INDEX('Data Entry_BD'!$AA:$AA,U14),"—")} -> #REF! | F33: {=IFERROR(INDEX('Data Entry_BD'!$AA:$AA,U15),"—")} -> #REF!
A34: K (Potassium) | B34: {=IFERROR(INDEX('Data Entry_BD'!$AB:$AB,X11),"—")} -> #REF! | C34: {=IFERROR(INDEX('Data Entry_BD'!$AB:$AB,X12),"—")} -> #REF! | D34: {=IFERROR(INDEX('Data Entry_BD'!$AB:$AB,X13),"—")} -> #REF! | E34: {=IFERROR(INDEX('Data Entry_BD'!$AB:$AB,U14),"—")} -> #REF! | F34: {=IFERROR(INDEX('Data Entry_BD'!$AB:$AB,U15),"—")} -> #REF!
A35: ADDITIVE (ppm)
A36: P (Phosphorus) | B36: {=IFERROR(INDEX(#REF!,X11),"—")} -> — | C36: {=IFERROR(INDEX(#REF!,X12),"—")} -> — | D36: {=IFERROR(INDEX(#REF!,X13),"—")} -> — | E36: {=IFERROR(INDEX(#REF!,U14),"—")} -> — | F36: {=IFERROR(INDEX(#REF!,U15),"—")} -> —
A37: Zn (Zinc) | B37: {=IFERROR(INDEX('Data Entry_BD'!$AF:$AF,X11),"—")} -> #REF! | C37: {=IFERROR(INDEX('Data Entry_BD'!$AF:$AF,X12),"—")} -> #REF! | D37: {=IFERROR(INDEX('Data Entry_BD'!$AF:$AF,X13),"—")} -> #REF! | E37: {=IFERROR(INDEX('Data Entry_BD'!$AF:$AF,U14),"—")} -> #REF! | F37: {=IFERROR(INDEX('Data Entry_BD'!$AF:$AF,U15),"—")} -> #REF!
A38: Ca (Calcium) | B38: {=IFERROR(INDEX('Data Entry_BD'!$AH:$AH,X11),"—")} | C38: {=IFERROR(INDEX('Data Entry_BD'!$AH:$AH,X12),"—")} | D38: {=IFERROR(INDEX('Data Entry_BD'!$AH:$AH,X13),"—")} | E38: {=IFERROR(INDEX('Data Entry_BD'!$AH:$AH,U14),"—")} -> #REF! | F38: {=IFERROR(INDEX('Data Entry_BD'!$AH:$AH,U15),"—")}
A39: Oxidation (Ab/cm) | E39: {=IFERROR(INDEX('_lookup'!$Q:$Q,MATCH($B$4,'_lookup'!$A:$A,0)),"")}
A40: PQ Index | B40: < 30 | C40: 30 – 60 | D40: > 60 | E40: {=IFERROR(INDEX('_lookup'!$R:$R,MATCH($B$4,'_lookup'!$A:$A,0)),"")} | F40: See trend chart
A42: ⚠ KEY ALERTS & RECOMMENDED ACTIONS (Latest Sample – auto-updated)
A43: # | B43: Alert / Recommendation
A44: 1 | B44: {=IFERROR(INDEX('_lookup'!$S:$S,MATCH($B$4,'_lookup'!$A:$A,0)),"")}
A45: 2 | B45: {=IFERROR(INDEX('_lookup'!$T:$T,MATCH($B$4,'_lookup'!$A:$A,0)),"")}
A46: 3 | B46: {=IFERROR(INDEX('_lookup'!$U:$U,MATCH($B$4,'_lookup'!$A:$A,0)),"")}
A47: 4 | B47: {=IFERROR(INDEX('_lookup'!$V:$V,MATCH($B$4,'_lookup'!$A:$A,0)),"")}
...

Sheet Analysis Report
B1: 📊 OIL ANALYSIS – EQUIPMENT DIAGNOSTIC DASHBOARD
B2: Select equipment from the dropdown below — all readings, KPIs, and recommendations update automatically
B4: SELECT EQUIPMENT: | E4: 111.AF040 (L) | I4: ← Choose equipment to update the report | X4: =IFERROR(minifs('Data Entry_BD'!$D$6:$D$430,'Data Entry_BD'!$A$6:$A$430,$E$4),"") -> 45545 | Y4: =IFERROR(MATCH(X4,'Data Entry_BD'!$D$6:$D$430,0)+4,"") -> 136
X5: =IFERROR(minifs('Data Entry_BD'!$D$6:$D$430,'Data Entry_BD'!$A$6:$A$430,$E$4,'Data Entry_BD'!$D$6:$D$430,">"&X4),"") -> 45726 | Y5: =IFERROR(MATCH(X5,'Data Entry_BD'!$D$6:$D$430,0)+4,"") -> 250
B6: ACCOUNT INFORMATION | H6: SAMPLE INFORMATION | M6: EQUIPMENT INFORMATION | X6: =IFERROR(minifs('Data Entry_BD'!$D$6:$D$430,'Data Entry_BD'!$A$6:$A$430,$E$4,'Data Entry_BD'!$D$6:$D$430,">"&X5),"") -> 45909 | Y6: =IFERROR(MATCH(X6,'Data Entry_BD'!$D$6:$D$430,0)+4,"") -> 396
B7: ID: | C7: =208948 -> 208948 | G7: Sample ID: | H7: {=IFERROR(INDEX(#REF!,MATCH(maxifs('Data Entry_BD'!$D$6:$D$430,'Data Entry_BD'!$A$6:$A$430,$E$4),'Data Entry_BD'!$D$6:$D$430,0)+4),"N/A")} -> N/A | K7: Asset Class: | L7: Circulating System | X7: =IFERROR(minifs('Data Entry_BD'!$D$6:$D$430,'Data Entry_BD'!$A$6:$A$430,$E$4,'Data Entry_BD'!$D$6:$D$430,">"&X6),"") -> 0 | Y7: =IFERROR(MATCH(X7,'Data Entry_BD'!$D$6:$D$430,0)+4,"")
B8: Name: | C8: Reliance Heavy Industries | G8: Service Level: | H8: {=IFERROR(INDEX(#REF!,MATCH(maxifs('Data Entry_BD'!$D$6:$D$430,'Data Entry_BD'!$A$6:$A$430,$E$4),'Data Entry_BD'!$D$6:$D$430,0)+4),"N/A")} -> N/A | K8: Manufacturer: | L8: N/A | X8: =IFERROR(minifs('Data Entry_BD'!$D$6:$D$430,'Data Entry_BD'!$A$6:$A$430,$E$4,'Data Entry_BD'!$D$6:$D$430,">"&X7),"") -> 45545 | Y8: =IFERROR(MATCH(X8,'Data Entry_BD'!$D$6:$D$430,0)+4,"") -> 136
B9: Address: | C9: Kattameya-Sokhna Road, Suez, EG | G9: Latest Sample Date: | H9: =IFERROR(TEXT(maxifs('Data Entry_BD'!$D$6:$D$430,'Data Entry_BD'!$A$6:$A$430,$E$4),"DD-MMM-YYYY"),"N/A") -> 09-Sep-2025 | K9: Model: | L9: N/A
G10: Tested Lubricant: | H10: {=IFERROR(INDEX(#REF!,MATCH(maxifs('Data Entry_BD'!$D$6:$D$430,'Data Entry_BD'!$A$6:$A$430,$E$4),'Data Entry_BD'!$D$6:$D$430,0)+4),"N/A")} -> N/A | K10: Lubricant: | L10: {=IFERROR(INDEX(#REF!,MATCH(maxifs('Data Entry_BD'!$D$6:$D$430,'Data Entry_BD'!$A$6:$A$430,$E$4),'Data Entry_BD'!$D$6:$D$430,0)+4),"N/A")} -> N/A
B12: SAMPLE DATA & TRENDS
B13: Parameter | C13: Sample History (Last 5 — Oldest → Latest)
B14: Parameter | C14: =IFERROR(TEXT(X4,"dd-mmm-yy"),"—") -> 10-Sep-24 | D14: =IFERROR(TEXT(X5,"dd-mmm-yy"),"—") -> 10-Mar-25 | E14: =IFERROR(TEXT(X6,"dd-mmm-yy"),"—") -> 09-Sep-25 | F14: =IFERROR(TEXT(X7,"dd-mmm-yy"),"—") -> 30-Dec-99 | G14: =IFERROR(TEXT(X8,"dd-mmm-yy"),"—") -> 10-Sep-24
B15: LUBRICANT
B16: Report Status | C16: {=IFERROR(INDEX('Data Entry_BD'!$E:$E,Y4),"—")} -> Normal | D16: {=IFERROR(INDEX('Data Entry_BD'!$E:$E,Y5),"—")} -> Caution | E16: {=IFERROR(INDEX('Data Entry_BD'!$E:$E,Y6),"—")} -> Normal | F16: {=IFERROR(INDEX('Data Entry_BD'!$E:$E,Y7),"—")} | G16: {=IFERROR(INDEX('Data Entry_BD'!$E:$E,Y8),"—")} -> Normal
B17: Visc@40°C (cSt) | C17: {=IFERROR(INDEX('Data Entry_BD'!$M:$M,Y4),"—")} -> 66.3 | D17: {=IFERROR(INDEX('Data Entry_BD'!$M:$M,Y5),"—")} -> 430.6 | E17: {=IFERROR(INDEX('Data Entry_BD'!$M:$M,Y6),"—")} -> 46 | F17: {=IFERROR(INDEX('Data Entry_BD'!$M:$M,Y7),"—")} | G17: {=IFERROR(INDEX('Data Entry_BD'!$M:$M,Y8),"—")} -> 66.3
B18: Water (Vol%) | C18: {=IFERROR(INDEX('Data Entry_BD'!$P:$P,Y4),"—")} -> 0.003 | D18: {=IFERROR(INDEX('Data Entry_BD'!$P:$P,Y5),"—")} -> 0.06 | E18: {=IFERROR(INDEX('Data Entry_BD'!$P:$P,Y6),"—")} -> 0.01 | F18: {=IFERROR(INDEX('Data Entry_BD'!$P:$P,Y7),"—")} | G18: {=IFERROR(INDEX('Data Entry_BD'!$P:$P,Y8),"—")} -> 0.003
B19: WEAR (ppm)
B20: Fe (Iron) | C20: {=IFERROR(INDEX('Data Entry_BD'!$T:$T,Y4),"—")} -> 3 | D20: {=IFERROR(INDEX('Data Entry_BD'!$T:$T,Y5),"—")} -> 8 | E20: {=IFERROR(INDEX('Data Entry_BD'!$T:$T,Y6),"—")} -> 7 | F20: {=IFERROR(INDEX('Data Entry_BD'!$T:$T,Y7),"—")} | G20: {=IFERROR(INDEX('Data Entry_BD'!$T:$T,Y8),"—")} -> 3
B21: Al (Aluminum) | C21: {=IFERROR(INDEX('Data Entry_BD'!$U:$U,Y4),"—")} -> 2 | D21: {=IFERROR(INDEX('Data Entry_BD'!$U:$U,Y5),"—")} -> 20 | E21: {=IFERROR(INDEX('Data Entry_BD'!$U:$U,Y6),"—")} -> 11 | F21: {=IFERROR(INDEX('Data Entry_BD'!$U:$U,Y7),"—")} | G21: {=IFERROR(INDEX('Data Entry_BD'!$U:$U,Y8),"—")} -> 2
B22: Cu (Copper) | C22: {=IFERROR(INDEX('Data Entry_BD'!$V:$V,Y4),"—")} -> 0 | D22: {=IFERROR(INDEX('Data Entry_BD'!$V:$V,Y5),"—")} -> 2 | E22: {=IFERROR(INDEX('Data Entry_BD'!$V:$V,Y6),"—")} -> 0 | F22: {=IFERROR(INDEX('Data Entry_BD'!$V:$V,Y7),"—")} | G22: {=IFERROR(INDEX('Data Entry_BD'!$V:$V,Y8),"—")} -> 0
B23: Cr (Chromium) | C23: {=IFERROR(INDEX('Data Entry_BD'!$W:$W,Y4),"—")} -> 0 | D23: {=IFERROR(INDEX('Data Entry_BD'!$W:$W,Y5),"—")} -> 0 | E23: {=IFERROR(INDEX('Data Entry_BD'!$W:$W,Y6),"—")} -> 0 | F23: {=IFERROR(INDEX('Data Entry_BD'!$W:$W,Y7),"—")} | G23: {=IFERROR(INDEX('Data Entry_BD'!$W:$W,Y8),"—")} -> 0
B24: CONTAM (ppm)
B25: Si (Silicon) | C25: {=IFERROR(INDEX('Data Entry_BD'!$Z:$Z,Y4),"—")} -> 0 | D25: {=IFERROR(INDEX('Data Entry_BD'!$Z:$Z,Y5),"—")} -> 0 | E25: {=IFERROR(INDEX('Data Entry_BD'!$Z:$Z,Y6),"—")} -> 0 | F25: {=IFERROR(INDEX('Data Entry_BD'!$Z:$Z,Y7),"—")} | G25: {=IFERROR(INDEX('Data Entry_BD'!$Z:$Z,Y8),"—")} -> 0
B26: Na (Sodium) | C26: {=IFERROR(INDEX('Data Entry_BD'!$AA:$AA,Y4),"—")} -> 0 | D26: {=IFERROR(INDEX('Data Entry_BD'!$AA:$AA,Y5),"—")} -> 1 | E26: {=IFERROR(INDEX('Data Entry_BD'!$AA:$AA,Y6),"—")} -> 0 | F26: {=IFERROR(INDEX('Data Entry_BD'!$AA:$AA,Y7),"—")} | G26: {=IFERROR(INDEX('Data Entry_BD'!$AA:$AA,Y8),"—")} -> 0
B27: K (Potassium) | C27: {=IFERROR(INDEX('Data Entry_BD'!$AB:$AB,Y4),"—")} -> 4 | D27: {=IFERROR(INDEX('Data Entry_BD'!$AB:$AB,Y5),"—")} -> 13 | E27: {=IFERROR(INDEX('Data Entry_BD'!$AB:$AB,Y6),"—")} -> 0 | F27: {=IFERROR(INDEX('Data Entry_BD'!$AB:$AB,Y7),"—")} | G27: {=IFERROR(INDEX('Data Entry_BD'!$AB:$AB,Y8),"—")} -> 4
B28: ADDITIVE (ppm)
B29: P (Phosphorus) | C29: {=IFERROR(INDEX(#REF!,Y4),"—")} -> — | D29: {=IFERROR(INDEX(#REF!,Y5),"—")} -> — | E29: {=IFERROR(INDEX(#REF!,Y6),"—")} -> — | F29: {=IFERROR(INDEX(#REF!,Y7),"—")} -> — | G29: {=IFERROR(INDEX(#REF!,Y8),"—")} -> —
B30: Zn (Zinc) | C30: {=IFERROR(INDEX('Data Entry_BD'!$AF:$AF,Y4),"—")} -> 0 | D30: {=IFERROR(INDEX('Data Entry_BD'!$AF:$AF,Y5),"—")} -> 3 | E30: {=IFERROR(INDEX('Data Entry_BD'!$AF:$AF,Y6),"—")} -> 0 | F30: {=IFERROR(INDEX('Data Entry_BD'!$AF:$AF,Y7),"—")} | G30: {=IFERROR(INDEX('Data Entry_BD'!$AF:$AF,Y8),"—")} -> 0
B31: Ca (Calcium) | C31: {=IFERROR(INDEX('Data Entry_BD'!$AH:$AH,Y4),"—")} -> 19 | D31: {=IFERROR(INDEX('Data Entry_BD'!$AH:$AH,Y5),"—")} -> 18 | E31: {=IFERROR(INDEX('Data Entry_BD'!$AH:$AH,Y6),"—")} -> 702 | F31: {=IFERROR(INDEX('Data Entry_BD'!$AH:$AH,Y7),"—")} | G31: {=IFERROR(INDEX('Data Entry_BD'!$AH:$AH,Y8),"—")} -> 19
B34: RECOMMENDATIONS / ACTIONS REQUIRED
B35: Alert Type: | C35: {=IFERROR(INDEX('Data Entry_BD'!$AI:$AI,MATCH(maxifs('Data Entry_BD'!$D$6:$D$430,'Data Entry_BD'!$A$6:$A$430,$E$4),'Data Entry_BD'!$D$6:$D$430,0)+4),"N/A")} -> Normal - No Action Required | J35: Contam. Rating: | K35: {=IFERROR(INDEX(#REF!,MATCH(maxifs('Data Entry_BD'!$D$6:$D$430,'Data Entry_BD'!$A$6:$A$430,$E$4),'Data Entry_BD'!$D$6:$D$430,0)+4),"N/A")} -> N/A
B36: RECOMMENDED ACTION (LATEST SAMPLE)
B37: {=IFERROR(INDEX('Data Entry_BD'!$AJ:$AJ,MATCH(maxifs('Data Entry_BD'!$D$6:$D$430,'Data Entry_BD'!$A$6:$A$430,$E$4),'Data Entry_BD'!$D$6:$D$430,0)+4),"N/A")} -> Continue routine monitoring and sampling schedule
B39: RECOMMENDATION HISTORY (ALL SAMPLES — OLDEST → LATEST)
B40: Sample Date | D40: Report Status | F40: Alert Type | H40: Contam. | I40: Recommendation / Action
B41: =IFERROR(TEXT(X4,"dd-mmm-yy"),"—") -> 10-Sep-24 | D41: {=IFERROR(INDEX('Data Entry_BD'!$E:$E,Y4),"—")} -> Normal | F41: {=IFERROR(INDEX('Data Entry_BD'!$AI:$AI,Y4),"—")} -> Normal - No Action Required | H41: =IFERROR(INDEX(#REF!,Y4),"—") -> — | I41: {=IFERROR(INDEX('Data Entry_BD'!$AJ:$AJ,Y4),"—")} -> Continue routine monitoring and sampling schedule
B42: =IFERROR(TEXT(X5,"dd-mmm-yy"),"—") -> 10-Mar-25 | D42: {=IFERROR(INDEX('Data Entry_BD'!$E:$E,Y5),"—")} -> Caution | F42: {=IFERROR(INDEX('Data Entry_BD'!$AI:$AI,Y5),"—")} -> Moisture Caution | H42: =IFERROR(INDEX(#REF!,Y5),"—") -> — | I42: {=IFERROR(INDEX('Data Entry_BD'!$AJ:$AJ,Y5),"—")} -> Moisture detected - check breathers and seals
B43: =IFERROR(TEXT(X6,"dd-mmm-yy"),"—") -> 09-Sep-25 | D43: {=IFERROR(INDEX('Data Entry_BD'!$E:$E,Y6),"—")} -> Normal | F43: {=IFERROR(INDEX('Data Entry_BD'!$AI:$AI,Y6),"—")} -> Normal - No Action Required | H43: =IFERROR(INDEX(#REF!,Y6),"—") -> — | I43: {=IFERROR(INDEX('Data Entry_BD'!$AJ:$AJ,Y6),"—")} -> Continue routine monitoring and sampling schedule
B44: =IFERROR(TEXT(X7,"dd-mmm-yy"),"—") -> 30-Dec-99 | D44: {=IFERROR(INDEX('Data Entry_BD'!$E:$E,Y7),"—")} | F44: {=IFERROR(INDEX('Data Entry_BD'!$AI:$AI,Y7),"—")} | H44: =IFERROR(INDEX(#REF!,Y7),"—") -> — | I44: {=IFERROR(INDEX('Data Entry_BD'!$AJ:$AJ,Y7),"—")}
B45: =IFERROR(TEXT(X8,"dd-mmm-yy"),"—") -> 10-Sep-24 | D45: {=IFERROR(INDEX('Data Entry_BD'!$E:$E,Y8),"—")} -> Normal | F45: {=IFERROR(INDEX('Data Entry_BD'!$AI:$AI,Y8),"—")} -> Normal - No Action Required | H45: =IFERROR(INDEX(#REF!,Y8),"—") -> — | I45: {=IFERROR(INDEX('Data Entry_BD'!$AJ:$AJ,Y8),"—")} -> Continue routine monitoring and sampling schedule
...

Sheet Oil Sample Tracker 1
A1: Equipment | B1: Last sample | C1: interval Days | D1: INTERVAL | E1: 44743 | F1: 44774 | G1: 44805 | H1: 44835 | I1: 45618 | J1: 44896 | K1: 44927 | L1: 44958 | M1: 44986 | N1: 45017 | O1: 45047 | P1: 45078 | Q1: 45108 | R1: 45139 | S1: 45170 | T1: 45200 | U1: 45231 | V1: 45261 | W1: 45292 | X1: 45323 | Y1: 45352 | Z1: 45383 | AA1: 45413 | AB1: 45444 | AC1: 45474 | AD1: 45505 | AE1: 45536 | AF1: 45566 | AG1: 45597 | AH1: 45627 | AI1: 45658 | AJ1: 45689 | AK1: 45717 | AL1: 45748 | AM1: 45778 | AN1: 45809 | AO1: 45839 | AP1: 45870 | AQ1: 45901 | AR1: 45931 | AS1: 45962 | AT1: 45992 | AU1: 46023 | AV1: 46054 | AW1: 46082 | AX1: 46113 | AY1: 46143 | AZ1: 46174 | BA1: 46204 | BB1: 46235 | BC1: 46266 | BD1: 46296 | BE1: 46327 | BF1: 46357 | BG1: 46185 | BH1: 46187 | BI1: 46193 | BJ1: 46183
A2: 111.AF040 (L) | B2: 46183 | C2: 210 | D2: 6 Months | E2: CAUTION | F2: CAUTION | G2: ALERT | L2: NORMAL | R2: NORMAL | S2: MISSING | X2: MISSING | AD2: MISSING | AE2: NORMAL | AJ2: ALERT | AP2: MISSING | AQ2: ALERT | AR2: CAUTION | AX2: CAUTION | BG2: Normal | BH2: Alert | BI2: Caution | BJ2: Normal
A3: 111.AF040 (R) | B3: =IFERROR( INDEX($E$1:$AAA$1, MATCH(2, 1/(($E3:$AAA3="NORMAL")+($E3:$AAA3="CAUTION")+($E3:$AAA3="ALERT")+($E3:$AAA3="Oil changed")), 1) ), "Missing") -> 46113 | C3: 210 | D3: 6 Months | F3: CAUTION | L3: NORMAL | R3: NORMAL | S3: MISSING | X3: MISSING | AD3: MISSING | AE3: CAUTION | AF3: NORMAL | AL3: MISSING | AR3: NORMAL | AV3: NORMAL | AX3: ALERT
A4: 111.AF060 (L) | B4: =IFERROR( INDEX($E$1:$AAA$1, MATCH(2, 1/(($E4:$AAA4="NORMAL")+($E4:$AAA4="CAUTION")+($E4:$AAA4="ALERT")+($E4:$AAA4="Oil changed")), 1) ), "Missing") -> 46113 | C4: 210 | D4: 6 Months | F4: NORMAL | L4: ALERT | R4: NORMAL | S4: MISSING | X4: MISSING | AD4: MISSING | AE4: CAUTION | AF4: CAUTION | AL4: MISSING | AR4: CAUTION | AX4: NORMAL
A5: 111.AF060 (R) | B5: =IFERROR( INDEX($E$1:$AAA$1, MATCH(2, 1/(($E5:$AAA5="NORMAL")+($E5:$AAA5="CAUTION")+($E5:$AAA5="ALERT")+($E5:$AAA5="Oil changed")), 1) ), "Missing") -> 46113 | C5: 210 | D5: 6 Months | F5: CAUTION | L5: ALERT | R5: NORMAL | S5: MISSING | X5: MISSING | AD5: MISSING | AE5: NORMAL | AJ5: NORMAL | AP5: MISSING | AQ5: NORMAL | AW5: CAUTION | AX5: Oil changed
A6: 111.BC210 | B6: =IFERROR( INDEX($E$1:$AAA$1, MATCH(2, 1/(($E6:$AAA6="NORMAL")+($E6:$AAA6="CAUTION")+($E6:$AAA6="ALERT")+($E6:$AAA6="Oil changed")), 1) ), "Missing") -> 46113 | C6: 210 | D6: 6 Months | F6: ALERT | G6: ALERT | L6: CAUTION | R6: ALERT | S6: MISSING | X6: MISSING | AA6: ALERT | AB6: ALERT | AE6: ALERT | AJ6: CAUTION | AP6: MISSING | AQ6: ALERT | AW6: ALERT | AX6: Oil changed
A7: 111.BC330 (L1) | B7: =IFERROR( INDEX($E$1:$AAA$1, MATCH(2, 1/(($E7:$AAA7="NORMAL")+($E7:$AAA7="CAUTION")+($E7:$AAA7="ALERT")+($E7:$AAA7="Oil changed")), 1) ), "Missing") -> 46113 | C7: 120 | D7: 3 Months | E7: NORMAL | H7: MISSING | K7: NORMAL | N7: MISSING | Q7: CAUTION | R7: NORMAL | S7: MISSING | U7: MISSING | X7: MISSING | AA7: MISSING | AC7: CAUTION | AE7: CAUTION | AG7: CAUTION | AJ7: MISSING | AM7: MISSING | AN7: NORMAL | AQ7: MISSING | AR7: MISSING | AS7: CAUTION | AV7: MISSING | AW7: CAUTION | AX7: CAUTION
A8: 111.BC330 (L2) | B8: =IFERROR( INDEX($E$1:$AAA$1, MATCH(2, 1/(($E8:$AAA8="NORMAL")+($E8:$AAA8="CAUTION")+($E8:$AAA8="ALERT")+($E8:$AAA8="Oil changed")), 1) ), "Missing") -> 46054 | C8: 120 | D8: 3 Months | E8: NORMAL | H8: MISSING | K8: NORMAL | N8: MISSING | Q8: NORMAL | S8: MISSING | T8: MISSING | W8: MISSING | Z8: MISSING | AC8: CAUTION | AE8: CAUTION | AG8: CAUTION | AJ8: MISSING | AM8: MISSING | AN8: CAUTION | AQ8: MISSING | AR8: MISSING | AS8: NORMAL | AV8: NORMAL
A9: 111.BC330 (R1) | B9: =IFERROR( INDEX($E$1:$AAA$1, MATCH(2, 1/(($E9:$AAA9="NORMAL")+($E9:$AAA9="CAUTION")+($E9:$AAA9="ALERT")+($E9:$AAA9="Oil changed")), 1) ), "Missing") -> 46054 | C9: 120 | D9: 3 Months | E9: NORMAL | H9: MISSING | K9: CAUTION | L9: CAUTION | O9: MISSING | Q9: CAUTION | R9: NORMAL | S9: MISSING | U9: MISSING | X9: MISSING | AA9: MISSING | AC9: ALERT | AE9: CAUTION | AG9: NORMAL | AJ9: MISSING | AM9: MISSING | AN9: CAUTION | AQ9: MISSING | AR9: MISSING | AS9: ALERT | AT9: NORMAL | AV9: NORMAL
A10: 111.BC330 (R2) | B10: =IFERROR( INDEX($E$1:$AAA$1, MATCH(2, 1/(($E10:$AAA10="NORMAL")+($E10:$AAA10="CAUTION")+($E10:$AAA10="ALERT")+($E10:$AAA10="Oil changed")), 1) ), "Missing") -> 46113 | C10: 120 | D10: 3 Months | E10: NORMAL | H10: MISSING | K10: CAUTION | L10: NORMAL | O10: MISSING | Q10: NORMAL | S10: MISSING | T10: MISSING | W10: MISSING | Z10: MISSING | AC10: CAUTION | AE10: CAUTION | AG10: CAUTION | AJ10: MISSING | AM10: MISSING | AN10: CAUTION | AQ10: MISSING | AR10: MISSING | AS10: CAUTION | AV10: MISSING | AX10: NORMAL
A11: 111.HC100 (HY) | B11: =IFERROR( INDEX($E$1:$AAA$1, MATCH(2, 1/(($E11:$AAA11="NORMAL")+($E11:$AAA11="CAUTION")+($E11:$AAA11="ALERT")+($E11:$AAA11="Oil changed")), 1) ), "Missing") -> 46054 | C11: 210 | D11: 6 Months | E11: CAUTION | K11: NORMAL | Q11: NORMAL | S11: MISSING | W11: MISSING | AA11: ALERT | AB11: ALERT | AC11: NORMAL | AI11: ALERT | AJ11: NORMAL | AP11: MISSING | AQ11: NORMAL | AV11: NORMAL
A12: 111.HC100 (IR) | B12: =IFERROR( INDEX($E$1:$AAA$1, MATCH(2, 1/(($E12:$AAA12="NORMAL")+($E12:$AAA12="CAUTION")+($E12:$AAA12="ALERT")+($E12:$AAA12="Oil changed")), 1) ), "Missing") -> 46113 | C12: 120 | D12: 3 Months | E12: CAUTION | H12: MISSING | K12: CAUTION | L12: ALERT | N12: ALERT | Q12: ALERT | S12: MISSING | T12: MISSING | W12: MISSING | Z12: MISSING | AA12: ALERT | AB12: ALERT | AC12: ALERT | AF12: MISSING | AI12: ALERT | AJ12: CAUTION | AM12: MISSING | AN12: CAUTION | AQ12: ALERT | AR12: ALERT | AU12: MISSING | AV12: MISSING | AX12: Oil changed
A13: 111.HC100 (RGB) | B13: =IFERROR( INDEX($E$1:$AAA$1, MATCH(2, 1/(($E13:$AAA13="NORMAL")+($E13:$AAA13="CAUTION")+($E13:$AAA13="ALERT")+($E13:$AAA13="Oil changed")), 1) ), "Missing") -> 46113 | C13: 120 | D13: 3 Months | E13: NORMAL | H13: MISSING | K13: ALERT | L13: NORMAL | O13: MISSING | Q13: ALERT | S13: MISSING | T13: NORMAL | W13: MISSING | Z13: MISSING | AA13: CAUTION | AB13: CAUTION | AC13: ALERT | AF13: MISSING | AI13: CAUTION | AL13: MISSING | AM13: MISSING | AN13: CAUTION | AQ13: ALERT | AR13: ALERT | AU13: MISSING | AV13: MISSING | AX13: Oil changed
A14: 123.BC100 | B14: =IFERROR( INDEX($E$1:$AAA$1, MATCH(2, 1/(($E14:$AAA14="NORMAL")+($E14:$AAA14="CAUTION")+($E14:$AAA14="ALERT")+($E14:$AAA14="Oil changed")), 1) ), "Missing") -> 46054 | C14: 210 | D14: 6 Months | F14: NORMAL | L14: NORMAL | R14: CAUTION | S14: MISSING | X14: MISSING | AB14: NORMAL | AI14: NORMAL | AN14: NORMAL | AT14: NORMAL | AV14: NORMAL
A15: 123.BC200 | B15: =IFERROR( INDEX($E$1:$AAA$1, MATCH(2, 1/(($E15:$AAA15="NORMAL")+($E15:$AAA15="CAUTION")+($E15:$AAA15="ALERT")+($E15:$AAA15="Oil changed")), 1) ), "Missing") -> 46082 | C15: 210 | D15: 6 Months | F15: NORMAL | L15: NORMAL | R15: NORMAL | S15: MISSING | X15: MISSING | AB15: ALERT | AC15: CAUTION | AI15: CAUTION | AJ15: CAUTION | AP15: MISSING | AQ15: ALERT | AR15: ALERT | AW15: CAUTION
A16: 131.BC100 | B16: =IFERROR( INDEX($E$1:$AAA$1, MATCH(2, 1/(($E16:$AAA16="NORMAL")+($E16:$AAA16="CAUTION")+($E16:$AAA16="ALERT")+($E16:$AAA16="Oil changed")), 1) ), "Missing") -> 46054 | C16: 210 | D16: 6 Months | F16: NORMAL | L16: NORMAL | R16: NORMAL | S16: MISSING | X16: MISSING | AB16: NORMAL | AI16: CAUTION | AN16: NORMAL | AT16: NORMAL | AV16: NORMAL
A17: 131.BC500 (M01) | B17: =IFERROR( INDEX($E$1:$AAA$1, MATCH(2, 1/(($E17:$AAA17="NORMAL")+($E17:$AAA17="CAUTION")+($E17:$AAA17="ALERT")+($E17:$AAA17="Oil changed")), 1) ), "Missing") -> 46113 | C17: 210 | D17: 6 Months | F17: NORMAL | L17: NORMAL | R17: CAUTION | S17: MISSING | X17: MISSING | AC17: MISSING | AD17: MISSING | AE17: CAUTION | AJ17: ALERT | AP17: MISSING | AQ17: ALERT | AR17: ALERT | AW17: ALERT | AX17: Oil changed
A18: 131.BC500 (M02) | B18: =IFERROR( INDEX($E$1:$AAA$1, MATCH(2, 1/(($E18:$AAA18="NORMAL")+($E18:$AAA18="CAUTION")+($E18:$AAA18="ALERT")+($E18:$AAA18="Oil changed")), 1) ), "Missing") -> 46113 | C18: 210 | D18: 6 Months | F18: NORMAL | L18: NORMAL | R18: CAUTION | S18: MISSING | X18: MISSING | AC18: MISSING | AD18: MISSING | AE18: CAUTION | AJ18: CAUTION | AP18: MISSING | AQ18: ALERT | AR18: ALERT | AW18: CAUTION | AX18: Oil changed
A19: 131.RE300 | B19: =IFERROR( INDEX($E$1:$AAA$1, MATCH(2, 1/(($E19:$AAA19="NORMAL")+($E19:$AAA19="CAUTION")+($E19:$AAA19="ALERT")+($E19:$AAA19="Oil changed")), 1) ), "Missing") -> 46113 | C19: 210 | D19: 6 Months | G19: NORMAL | M19: ALERT | S19: MISSING | Y19: MISSING | AA19: CAUTION | AF19: NORMAL | AL19: MISSING | AP19: MISSING | AR19: ALERT | AS19: ALERT | AX19: Oil changed
A20: 131.RE300.M11 | B20: =IFERROR( INDEX($E$1:$AAA$1, MATCH(2, 1/(($E20:$AAA20="NORMAL")+($E20:$AAA20="CAUTION")+($E20:$AAA20="ALERT")+($E20:$AAA20="Oil changed")), 1) ), "Missing") -> 46113 | C20: 210 | D20: 6 Months | G20: NORMAL | J20: CAUTION | K20: NORMAL | M20: NORMAL | S20: MISSING | Y20: MISSING | AA20: ALERT | AF20: CAUTION | AL20: MISSING | AP20: MISSING | AR20: ALERT | AS20: ALERT | AX20: Oil changed
A21: 131.RE300.M12 | B21: =IFERROR( INDEX($E$1:$AAA$1, MATCH(2, 1/(($E21:$AAA21="NORMAL")+($E21:$AAA21="CAUTION")+($E21:$AAA21="ALERT")+($E21:$AAA21="Oil changed")), 1) ), "Missing") -> 46113 | C21: 210 | D21: 6 Months | G21: NORMAL | J21: NORMAL | M21: NORMAL | S21: MISSING | U21: NORMAL | AA21: ALERT | AF21: CAUTION | AL21: MISSING | AN21: ALERT | AQ21: ALERT | AR21: ALERT | AX21: Oil changed
A22: 131.ST200 (HY) | B22: =IFERROR( INDEX($E$1:$AAA$1, MATCH(2, 1/(($E22:$AAA22="NORMAL")+($E22:$AAA22="CAUTION")+($E22:$AAA22="ALERT")+($E22:$AAA22="Oil changed")), 1) ), "Missing") -> 46113 | C22: 210 | D22: 6 Months | G22: CAUTION | H22: NORMAL | M22: CAUTION | N22: ALERT | S22: MISSING | T22: MISSING | Z22: MISSING | AA22: NORMAL | AF22: CAUTION | AL22: MISSING | AN22: CAUTION | AR22: ALERT | AS22: ALERT | AX22: Oil changed
A23: 131.ST200.M11 | B23: =IFERROR( INDEX($E$1:$AAA$1, MATCH(2, 1/(($E23:$AAA23="NORMAL")+($E23:$AAA23="CAUTION")+($E23:$AAA23="ALERT")+($E23:$AAA23="Oil changed")), 1) ), "Missing") -> 46113 | C23: 210 | D23: 6 Months | G23: ALERT | H23: CAUTION | I23: ALERT | M23: NORMAL | S23: MISSING | T23: NORMAL | Z23: MISSING | AA23: ALERT | AF23: ALERT | AG23: ALERT | AM23: MISSING | AN23: ALERT | AQ23: ALERT | AR23: ALERT | AS23: ALERT | AV23: ALERT | AX23: Oil changed
A24: 131.ST200.M12 | B24: =IFERROR( INDEX($E$1:$AAA$1, MATCH(2, 1/(($E24:$AAA24="NORMAL")+($E24:$AAA24="CAUTION")+($E24:$AAA24="ALERT")+($E24:$AAA24="Oil changed")), 1) ), "Missing") -> 46113 | C24: 210 | D24: 6 Months | G24: CAUTION | H24: CAUTION | M24: ALERT | S24: MISSING | T24: NORMAL | Z24: MISSING | AA24: ALERT | AF24: ALERT | AG24: ALERT | AM24: MISSING | AP24: MISSING | AS24: ALERT | AV24: ALERT | AX24: Oil changed
A25: 261.CV600 | B25: =IFERROR( INDEX($E$1:$AAA$1, MATCH(2, 1/(($E25:$AAA25="NORMAL")+($E25:$AAA25="CAUTION")+($E25:$AAA25="ALERT")+($E25:$AAA25="Oil changed")), 1) ), "Missing") -> 46054 | C25: 365 | D25: If needed | O25: ALERT | AR25: NORMAL | AV25: NORMAL
A26: 261.SH050 (T) | B26: =IFERROR( INDEX($E$1:$AAA$1, MATCH(2, 1/(($E26:$AAA26="NORMAL")+($E26:$AAA26="CAUTION")+($E26:$AAA26="ALERT")+($E26:$AAA26="Oil changed")), 1) ), "Missing") -> 46082 | C26: 365 | D26: If needed | G26: NORMAL | H26: ALERT | K26: NORMAL | O26: ALERT | W26: ALERT | X26: NORMAL | AF26: CAUTION | AG26: CAUTION | AJ26: ALERT | AN26: ALERT | AQ26: NORMAL | AR26: ALERT | AS26: ALERT | AV26: ALERT | AW26: NORMAL
A27: 263.AF010 | B27: =IFERROR( INDEX($E$1:$AAA$1, MATCH(2, 1/(($E27:$AAA27="NORMAL")+($E27:$AAA27="CAUTION")+($E27:$AAA27="ALERT")+($E27:$AAA27="Oil changed")), 1) ), "Missing") -> 46113 | C27: 365 | D27: If needed | AG27: ALERT | AV27: ALERT | AX27: ALERT
A28: 321.BE220 | B28: =IFERROR( INDEX($E$1:$AAA$1, MATCH(2, 1/(($E28:$AAA28="NORMAL")+($E28:$AAA28="CAUTION")+($E28:$AAA28="ALERT")+($E28:$AAA28="Oil changed")), 1) ), "Missing") -> 45962 | C28: 210 | D28: 6 Months | G28: CAUTION | H28: NORMAL | M28: NORMAL | S28: MISSING | Y28: MISSING | AE28: MISSING | AF28: ALERT | AL28: MISSING | AP28: MISSING | AR28: Insufficient Sample | AS28: ALERT
A29: 321.FN400(Fr.B) | B29: =IFERROR( INDEX($E$1:$AAA$1, MATCH(2, 1/(($E29:$AAA29="NORMAL")+($E29:$AAA29="CAUTION")+($E29:$AAA29="ALERT")+($E29:$AAA29="Oil changed")), 1) ), "Missing") -> 46113 | C29: 210 | D29: 6 Months | E29: CAUTION | H29: NORMAL | M29: NORMAL | S29: MISSING | Y29: MISSING | AE29: MISSING | AF29: ALERT | AL29: MISSING | AP29: MISSING | AR29: ALERT | AW29: ALERT | AX29: ALERT
A30: 321.FN400(Fx.B) | B30: =IFERROR( INDEX($E$1:$AAA$1, MATCH(2, 1/(($E30:$AAA30="NORMAL")+($E30:$AAA30="CAUTION")+($E30:$AAA30="ALERT")+($E30:$AAA30="Oil changed")), 1) ), "Missing") -> 46113 | C30: 210 | D30: 6 Months | E30: CAUTION | H30: NORMAL | M30: NORMAL | S30: MISSING | Y30: MISSING | AE30: MISSING | AF30: ALERT | AL30: MISSING | AP30: MISSING | AR30: ALERT | AX30: ALERT
A31: 321.HY110 | B31: =IFERROR( INDEX($E$1:$AAA$1, MATCH(2, 1/(($E31:$AAA31="NORMAL")+($E31:$AAA31="CAUTION")+($E31:$AAA31="ALERT")+($E31:$AAA31="Oil changed")), 1) ), "Missing") -> 46113 | C31: 60 | D31: Monthly | E31: ALERT | F31: CAUTION | G31: NORMAL | H31: MISSING | I31: ALERT | J31: CAUTION | K31: NORMAL | L31: MISSING | M31: ALERT | N31: ALERT | O31: CAUTION | P31: MISSING | Q31: ALERT | R31: MISSING | S31: MISSING | T31: NORMAL | U31: CAUTION | V31: MISSING | W31: CAUTION | X31: CAUTION | Y31: MISSING | Z31: MISSING | AA31: MISSING | AB31: MISSING | AC31: ALERT | AD31: MISSING | AE31: ALERT | AF31: CAUTION | AG31: ALERT | AH31: MISSING | AI31: NORMAL | AJ31: MISSING | AK31: MISSING | AL31: MISSING | AM31: MISSING | AN31: CAUTION | AO31: MISSING | AP31: MISSING | AQ31: ALERT | AR31: ALERT | AS31: ALERT | AT31: NORMAL | AU31: MISSING | AV31: NORMAL | AW31: CAUTION | AX31: CAUTION
A32: 321.LQ120 (R1) | B32: =IFERROR( INDEX($E$1:$AAA$1, MATCH(2, 1/(($E32:$AAA32="NORMAL")+($E32:$AAA32="CAUTION")+($E32:$AAA32="ALERT")+($E32:$AAA32="Oil changed")), 1) ), "Missing") -> Missing | C32: 365 | D32: If needed | AV32: MISSING
A33: 321.LQ120 (R2) | B33: =IFERROR( INDEX($E$1:$AAA$1, MATCH(2, 1/(($E33:$AAA33="NORMAL")+($E33:$AAA33="CAUTION")+($E33:$AAA33="ALERT")+($E33:$AAA33="Oil changed")), 1) ), "Missing") -> Missing | C33: 365 | D33: If needed | AV33: MISSING
A34: 321.LQ120 (R3) | B34: =IFERROR( INDEX($E$1:$AAA$1, MATCH(2, 1/(($E34:$AAA34="NORMAL")+($E34:$AAA34="CAUTION")+($E34:$AAA34="ALERT")+($E34:$AAA34="Oil changed")), 1) ), "Missing") -> 46054 | C34: 365 | D34: If needed | X34: NORMAL | AV34: NORMAL
A35: 321.LQ120 (T) | B35: =IFERROR( INDEX($E$1:$AAA$1, MATCH(2, 1/(($E35:$AAA35="NORMAL")+($E35:$AAA35="CAUTION")+($E35:$AAA35="ALERT")+($E35:$AAA35="Oil changed")), 1) ), "Missing") -> 46113 | C35: 60 | D35: Monthly | E35: ALERT | F35: ALERT | G35: ALERT | H35: ALERT | I35: ALERT | J35: ALERT | K35: ALERT | L35: ALERT | M35: ALERT | N35: NORMAL | O35: NORMAL | P35: MISSING | Q35: ALERT | R35: MISSING | S35: MISSING | T35: ALERT | U35: ALERT | V35: ALERT | W35: ALERT | X35: MISSING | Y35: MISSING | Z35: MISSING | AA35: MISSING | AB35: NORMAL | AC35: NORMAL | AD35: MISSING | AE35: NORMAL | AF35: MISSING | AG35: NORMAL | AH35: MISSING | AI35: NORMAL | AJ35: MISSING | AK35: MISSING | AL35: MISSING | AM35: MISSING | AN35: NORMAL | AO35: MISSING | AP35: MISSING | AQ35: NORMAL | AR35: MISSING | AS35: CAUTION | AT35: CAUTION | AU35: MISSING | AV35: MISSING | AW35: CAUTION | AX35: CAUTION
A36: 321.LQ145(GB) | B36: =IFERROR( INDEX($E$1:$AAA$1, MATCH(2, 1/(($E36:$AAA36="NORMAL")+($E36:$AAA36="CAUTION")+($E36:$AAA36="ALERT")+($E36:$AAA36="Oil changed")), 1) ), "Missing") -> 46113 | C36: 60 | D36: Monthly | E36: NORMAL | F36: MISSING | G36: MISSING | H36: CAUTION | I36: MISSING | J36: MISSING | K36: NORMAL | L36: MISSING | M36: MISSING | N36: ALERT | O36: MISSING | P36: MISSING | Q36: ALERT | R36: MISSING | S36: MISSING | T36: MISSING | U36: MISSING | V36: MISSING | W36: MISSING | X36: MISSING | Y36: MISSING | Z36: MISSING | AA36: MISSING | AB36: MISSING | AC36: CAUTION | AD36: MISSING | AE36: CAUTION | AF36: MISSING | AG36: MISSING | AH36: MISSING | AI36: ALERT | AJ36: MISSING | AK36: MISSING | AL36: MISSING | AM36: MISSING | AN36: MISSING | AO36: MISSING | AP36: MISSING | AQ36: MISSING | AR36: MISSING | AS36: MISSING | AT36: MISSING | AU36: MISSING | AV36: MISSING | AW36: ALERT | AX36: ALERT
A37: 321.LQ145 (T) | B37: =IFERROR( INDEX($E$1:$AAA$1, MATCH(2, 1/(($E37:$AAA37="NORMAL")+($E37:$AAA37="CAUTION")+($E37:$AAA37="ALERT")+($E37:$AAA37="Oil changed")), 1) ), "Missing") -> 46113 | C37: 365 | D37: If needed | T37: ALERT | U37: ALERT | Y37: ALERT | AB37: ALERT | AE37: NORMAL | AN37: ALERT | AR37: NORMAL | AT37: ALERT | AX37: NORMAL
A38: 321.MD152 | B38: =IFERROR( INDEX($E$1:$AAA$1, MATCH(2, 1/(($E38:$AAA38="NORMAL")+($E38:$AAA38="CAUTION")+($E38:$AAA38="ALERT")+($E38:$AAA38="Oil changed")), 1) ), "Missing") -> 46113 | C38: 210 | D38: 6 Months | F38: ALERT | L38: CAUTION | R38: ALERT | S38: MISSING | T38: ALERT | U38: ALERT | V38: ALERT | AB38: MISSING | AE38: CAUTION | AF38: CAUTION | AG38: CAUTION | AM38: MISSING | AN38: CAUTION | AS38: ALERT | AX38: Oil changed
A39: 321.RF090 | B39: =IFERROR( INDEX($E$1:$AAA$1, MATCH(2, 1/(($E39:$AAA39="NORMAL")+($E39:$AAA39="CAUTION")+($E39:$AAA39="ALERT")+($E39:$AAA39="Oil changed")), 1) ), "Missing") -> 46054 | C39: 210 | D39: 6 Months | E39: ALERT | F39: ALERT | K39: NORMAL | Q39: CAUTION | R39: NORMAL | S39: MISSING | W39: ALERT | Y39: ALERT | AC39: ALERT | AF39: NORMAL | AG39: CAUTION | AM39: MISSING | AN39: NORMAL | AT39: MISSING | AV39: NORMAL
A40: R2.322.BE220 | B40: =IFERROR( INDEX($E$1:$AAA$1, MATCH(2, 1/(($E40:$AAA40="NORMAL")+($E40:$AAA40="CAUTION")+($E40:$AAA40="ALERT")+($E40:$AAA40="Oil changed")), 1) ), "Missing") -> 46113 | C40: 210 | D40: 6 Months | F40: NORMAL | M40: NORMAL | S40: MISSING | Y40: MISSING | AE40: MISSING | AF40: NORMAL | AL40: MISSING | AP40: MISSING | AR40: ALERT | AS40: ALERT | AX40: Oil changed
...

Sheet Oil Sample Tracker
A1: Equipment | B1: Jul-22 | C1: Aug-22 | D1: Sep-22 | E1: Oct-22 | F1: Nov-24 | G1: Dec-22 | H1: Jan-23 | I1: Feb-23 | J1: Mar-23 | K1: Apr-23 | L1: May-23 | M1: Jun-23 | N1: Jul-23 | O1: Aug-23 | P1: Sep-23 | Q1: Oct-23 | R1: Nov-23 | S1: Dec-23 | T1: Jan-24 | U1: Feb-24 | V1: Mar-24 | W1: Apr-24 | X1: May-24 | Y1: Jun-24 | Z1: Jul-24 | AA1: Aug-24 | AB1: Sep-24 | AC1: Oct-24 | AD1: Nov-24 | AE1: Dec-24 | AF1: Jan-25 | AG1: Feb-25 | AH1: Mar-25 | AI1: Apr-25 | AJ1: May-25 | AK1: Jun-25 | AL1: Jul-25 | AM1: Aug-25 | AN1: Sep-25 | AO1: Oct-25 | AP1: Nov-25 | AQ1: Dec-25 | AR1: Jan-26 | AS1: Feb-26 | AT1: Mar-26 | AU1: Apr-26 | AV1: May-26 | AW1: Jun-26 | AX1: Jul-26 | AY1: Aug-26 | AZ1: Sep-26 | BA1: Oct-26 | BB1: Nov-26 | BC1: Dec-26
A2: 111.AF040 (L) | B2: CAUTION | C2: CAUTION | D2: ALERT | I2: NORMAL | O2: NORMAL | P2: MISSING | U2: MISSING | AA2: MISSING | AB2: NORMAL | AG2: ALERT | AM2: MISSING | AN2: ALERT | AO2: CAUTION | AU2: CAUTION
A3: 111.AF040 (R) | C3: CAUTION | I3: NORMAL | O3: NORMAL | P3: MISSING | U3: MISSING | AA3: MISSING | AB3: CAUTION | AC3: NORMAL | AI3: MISSING | AO3: NORMAL | AS3: NORMAL | AU3: ALERT
A4: 111.AF060 (L) | C4: NORMAL | I4: ALERT | O4: NORMAL | P4: MISSING | U4: MISSING | AA4: MISSING | AB4: CAUTION | AC4: CAUTION | AI4: MISSING | AO4: CAUTION | AU4: NORMAL
A5: 111.AF060 (R) | C5: CAUTION | I5: ALERT | O5: NORMAL | P5: MISSING | U5: MISSING | AA5: MISSING | AB5: NORMAL | AG5: NORMAL | AM5: MISSING | AN5: NORMAL | AT5: CAUTION | AU5: Oil changed
A6: 111.BC210 | C6: ALERT | D6: ALERT | I6: CAUTION | O6: ALERT | P6: MISSING | U6: MISSING | X6: ALERT | Y6: ALERT | AB6: ALERT | AG6: CAUTION | AM6: MISSING | AN6: ALERT | AT6: ALERT | AU6: Oil changed
A7: 111.BC330 (L1) | B7: NORMAL | E7: MISSING | H7: NORMAL | K7: MISSING | N7: CAUTION | O7: NORMAL | P7: MISSING | R7: MISSING | U7: MISSING | X7: MISSING | Z7: CAUTION | AB7: CAUTION | AD7: CAUTION | AG7: MISSING | AJ7: MISSING | AK7: NORMAL | AN7: MISSING | AO7: MISSING | AP7: CAUTION | AS7: MISSING | AT7: CAUTION | AU7: CAUTION
A8: 111.BC330 (L2) | B8: NORMAL | E8: MISSING | H8: NORMAL | K8: MISSING | N8: NORMAL | P8: MISSING | Q8: MISSING | T8: MISSING | W8: MISSING | Z8: CAUTION | AB8: CAUTION | AD8: CAUTION | AG8: MISSING | AJ8: MISSING | AK8: CAUTION | AN8: MISSING | AO8: MISSING | AP8: NORMAL | AS8: NORMAL
A9: 111.BC330 (R1) | B9: NORMAL | E9: MISSING | H9: CAUTION | I9: CAUTION | L9: MISSING | N9: CAUTION | O9: NORMAL | P9: MISSING | R9: MISSING | U9: MISSING | X9: MISSING | Z9: ALERT | AB9: CAUTION | AD9: NORMAL | AG9: MISSING | AJ9: MISSING | AK9: CAUTION | AN9: MISSING | AO9: MISSING | AP9: ALERT | AQ9: NORMAL | AS9: NORMAL
A10: 111.BC330 (R2) | B10: NORMAL | E10: MISSING | H10: CAUTION | I10: NORMAL | L10: MISSING | N10: NORMAL | P10: MISSING | Q10: MISSING | T10: MISSING | W10: MISSING | Z10: CAUTION | AB10: CAUTION | AD10: CAUTION | AG10: MISSING | AJ10: MISSING | AK10: CAUTION | AN10: MISSING | AO10: MISSING | AP10: CAUTION | AS10: MISSING | AU10: NORMAL
A11: 111.HC100 (HY) | B11: CAUTION | H11: NORMAL | N11: NORMAL | P11: MISSING | T11: MISSING | X11: ALERT | Y11: ALERT | Z11: NORMAL | AF11: ALERT | AG11: NORMAL | AM11: MISSING | AN11: NORMAL | AS11: NORMAL
A12: 111.HC100 (IR) | B12: CAUTION | E12: MISSING | H12: CAUTION | I12: ALERT | K12: ALERT | N12: ALERT | P12: MISSING | Q12: MISSING | T12: MISSING | W12: MISSING | X12: ALERT | Y12: ALERT | Z12: ALERT | AC12: MISSING | AF12: ALERT | AG12: CAUTION | AJ12: MISSING | AK12: CAUTION | AN12: ALERT | AO12: ALERT | AR12: MISSING | AS12: MISSING | AU12: Oil changed
A13: 111.HC100 (RGB) | B13: NORMAL | E13: MISSING | H13: ALERT | I13: NORMAL | L13: MISSING | N13: ALERT | P13: MISSING | Q13: NORMAL | T13: MISSING | W13: MISSING | X13: CAUTION | Y13: CAUTION | Z13: ALERT | AC13: MISSING | AF13: CAUTION | AI13: MISSING | AJ13: MISSING | AK13: CAUTION | AN13: ALERT | AO13: ALERT | AR13: MISSING | AS13: MISSING | AU13: Oil changed
A14: 123.BC100 | C14: NORMAL | I14: NORMAL | O14: CAUTION | P14: MISSING | U14: MISSING | Y14: NORMAL | AF14: NORMAL | AK14: NORMAL | AQ14: NORMAL | AS14: NORMAL
A15: 123.BC200 | C15: NORMAL | I15: NORMAL | O15: NORMAL | P15: MISSING | U15: MISSING | Y15: ALERT | Z15: CAUTION | AF15: CAUTION | AG15: CAUTION | AM15: MISSING | AN15: ALERT | AO15: ALERT | AT15: CAUTION
A16: 131.BC100 | C16: NORMAL | I16: NORMAL | O16: NORMAL | P16: MISSING | U16: MISSING | Y16: NORMAL | AF16: CAUTION | AK16: NORMAL | AQ16: NORMAL | AS16: NORMAL
A17: 131.BC500 (M01) | C17: NORMAL | I17: NORMAL | O17: CAUTION | P17: MISSING | U17: MISSING | Z17: MISSING | AA17: MISSING | AB17: CAUTION | AG17: ALERT | AM17: MISSING | AN17: ALERT | AO17: ALERT | AT17: ALERT | AU17: Oil changed
A18: 131.BC500 (M02) | C18: NORMAL | I18: NORMAL | O18: CAUTION | P18: MISSING | U18: MISSING | Z18: MISSING | AA18: MISSING | AB18: CAUTION | AG18: CAUTION | AM18: MISSING | AN18: ALERT | AO18: ALERT | AT18: CAUTION | AU18: Oil changed
A19: 131.RE300 | D19: NORMAL | J19: ALERT | P19: MISSING | V19: MISSING | X19: CAUTION | AC19: NORMAL | AI19: MISSING | AM19: MISSING | AO19: ALERT | AP19: ALERT | AU19: Oil changed
A20: 131.RE300.M11 | D20: NORMAL | G20: CAUTION | H20: NORMAL | J20: NORMAL | P20: MISSING | V20: MISSING | X20: ALERT | AC20: CAUTION | AI20: MISSING | AM20: MISSING | AO20: ALERT | AP20: ALERT | AU20: Oil changed
A21: 131.RE300.M12 | D21: NORMAL | G21: NORMAL | J21: NORMAL | P21: MISSING | R21: NORMAL | X21: ALERT | AC21: CAUTION | AI21: MISSING | AK21: ALERT | AN21: ALERT | AO21: ALERT | AU21: Oil changed
A22: 131.ST200 (HY) | D22: CAUTION | E22: NORMAL | J22: CAUTION | K22: ALERT | P22: MISSING | Q22: MISSING | W22: MISSING | X22: NORMAL | AC22: CAUTION | AI22: MISSING | AK22: CAUTION | AO22: ALERT | AP22: ALERT | AU22: Oil changed
A23: 131.ST200.M11 | D23: ALERT | E23: CAUTION | F23: ALERT | J23: NORMAL | P23: MISSING | Q23: NORMAL | W23: MISSING | X23: ALERT | AC23: ALERT | AD23: ALERT | AJ23: MISSING | AK23: ALERT | AN23: ALERT | AO23: ALERT | AP23: ALERT | AS23: ALERT | AU23: Oil changed
A24: 131.ST200.M12 | D24: CAUTION | E24: CAUTION | J24: ALERT | P24: MISSING | Q24: NORMAL | W24: MISSING | X24: ALERT | AC24: ALERT | AD24: ALERT | AJ24: MISSING | AM24: MISSING | AP24: ALERT | AS24: ALERT | AU24: Oil changed
A25: 261.CV600 | L25: ALERT | AO25: NORMAL | AS25: NORMAL
A26: 261.SH050 (T) | D26: NORMAL | E26: ALERT | H26: NORMAL | L26: ALERT | T26: ALERT | U26: NORMAL | AC26: CAUTION | AD26: CAUTION | AG26: ALERT | AK26: ALERT | AN26: NORMAL | AO26: ALERT | AP26: ALERT | AS26: ALERT | AT26: NORMAL
A27: 263.AF010 | AD27: ALERT | AS27: ALERT | AU27: ALERT
A28: 321.BE220 | D28: CAUTION | E28: NORMAL | J28: NORMAL | P28: MISSING | V28: MISSING | AB28: MISSING | AC28: ALERT | AI28: MISSING | AM28: MISSING | AO28: Insufficient Sample | AP28: ALERT
A29: 321.FN400(Fr.B) | B29: CAUTION | E29: NORMAL | J29: NORMAL | P29: MISSING | V29: MISSING | AB29: MISSING | AC29: ALERT | AI29: MISSING | AM29: MISSING | AO29: ALERT | AT29: ALERT | AU29: ALERT
A30: 321.FN400(Fx.B) | B30: CAUTION | E30: NORMAL | J30: NORMAL | P30: MISSING | V30: MISSING | AB30: MISSING | AC30: ALERT | AI30: MISSING | AM30: MISSING | AO30: ALERT | AU30: ALERT
A31: 321.HY110 | B31: ALERT | C31: CAUTION | D31: NORMAL | E31: MISSING | F31: ALERT | G31: CAUTION | H31: NORMAL | I31: MISSING | J31: ALERT | K31: ALERT | L31: CAUTION | M31: MISSING | N31: ALERT | O31: MISSING | P31: MISSING | Q31: NORMAL | R31: CAUTION | S31: MISSING | T31: CAUTION | U31: CAUTION | V31: MISSING | W31: MISSING | X31: MISSING | Y31: MISSING | Z31: ALERT | AA31: MISSING | AB31: ALERT | AC31: CAUTION | AD31: ALERT | AE31: MISSING | AF31: NORMAL | AG31: MISSING | AH31: MISSING | AI31: MISSING | AJ31: MISSING | AK31: CAUTION | AL31: MISSING | AM31: MISSING | AN31: ALERT | AO31: ALERT | AP31: ALERT | AQ31: NORMAL | AR31: MISSING | AS31: NORMAL | AT31: CAUTION | AU31: CAUTION
A32: 321.LQ120 (R1) | AS32: MISSING
A33: 321.LQ120 (R2) | AS33: MISSING
A34: 321.LQ120 (R3) | U34: NORMAL | AS34: NORMAL
A35: 321.LQ120 (T) | B35: ALERT | C35: ALERT | D35: ALERT | E35: ALERT | F35: ALERT | G35: ALERT | H35: ALERT | I35: ALERT | J35: ALERT | K35: NORMAL | L35: NORMAL | M35: MISSING | N35: ALERT | O35: MISSING | P35: MISSING | Q35: ALERT | R35: ALERT | S35: ALERT | T35: ALERT | U35: MISSING | V35: MISSING | W35: MISSING | X35: MISSING | Y35: NORMAL | Z35: NORMAL | AA35: MISSING | AB35: NORMAL | AC35: MISSING | AD35: NORMAL | AE35: MISSING | AF35: NORMAL | AG35: MISSING | AH35: MISSING | AI35: MISSING | AJ35: MISSING | AK35: NORMAL | AL35: MISSING | AM35: MISSING | AN35: NORMAL | AO35: MISSING | AP35: CAUTION | AQ35: CAUTION | AR35: MISSING | AS35: MISSING | AT35: CAUTION | AU35: CAUTION
A36: 321.LQ145(GB) | B36: NORMAL | C36: MISSING | D36: MISSING | E36: CAUTION | F36: MISSING | G36: MISSING | H36: NORMAL | I36: MISSING | J36: MISSING | K36: ALERT | L36: MISSING | M36: MISSING | N36: ALERT | O36: MISSING | P36: MISSING | Q36: MISSING | R36: MISSING | S36: MISSING | T36: MISSING | U36: MISSING | V36: MISSING | W36: MISSING | X36: MISSING | Y36: MISSING | Z36: CAUTION | AA36: MISSING | AB36: CAUTION | AC36: MISSING | AD36: MISSING | AE36: MISSING | AF36: ALERT | AG36: MISSING | AH36: MISSING | AI36: MISSING | AJ36: MISSING | AK36: MISSING | AL36: MISSING | AM36: MISSING | AN36: MISSING | AO36: MISSING | AP36: MISSING | AQ36: MISSING | AR36: MISSING | AS36: MISSING | AT36: ALERT | AU36: ALERT
A37: 321.LQ145 (T) | Q37: ALERT | R37: ALERT | V37: ALERT | Y37: ALERT | AB37: NORMAL | AK37: ALERT | AO37: NORMAL | AQ37: ALERT | AU37: NORMAL
A38: 321.MD152 | C38: ALERT | I38: CAUTION | O38: ALERT | P38: MISSING | Q38: ALERT | R38: ALERT | S38: ALERT | Y38: MISSING | AB38: CAUTION | AC38: CAUTION | AD38: CAUTION | AJ38: MISSING | AK38: CAUTION | AP38: ALERT | AU38: Oil changed
A39: 321.RF090 | B39: ALERT | C39: ALERT | H39: NORMAL | N39: CAUTION | O39: NORMAL | P39: MISSING | T39: ALERT | V39: ALERT | Z39: ALERT | AC39: NORMAL | AD39: CAUTION | AJ39: MISSING | AK39: NORMAL | AQ39: MISSING | AS39: NORMAL
A40: R2.322.BE220 | C40: NORMAL | J40: NORMAL | P40: MISSING | V40: MISSING | AB40: MISSING | AC40: NORMAL | AI40: MISSING | AM40: MISSING | AO40: ALERT | AP40: ALERT | AU40: Oil changed
...

Sheet Oil Change Log
A1: 📊 OIL Changing LOG Sheet
A2: IF any equipment Frequancy change due to oil analysis , so the max Changing is 2 years
A3: Asset | B3: Asset Name | C3: Lubrication Points | D3: Frequncy | E3: Oil Type | F3: Brand | G3: Qty (ltr.) | H3: Change Dates | J3: Last change | K3: Next Oil Change | L3: Status | M3: Last Modified
A4: 111.AF040 (L) | B4: Apron Feeder | C4: {=IF(A4:A153="", "", XLOOKUP(A4:A153, 'Equipment Registry'!A2:A153, 'Equipment Registry'!B2:B153, "Not Found"))} -> Clay apron feeder left geared motor | D4: Oil Analysis | E4: Mobil SHC 630 | F4: Mobil | G4: 41 | J4: 44378 | K4: =EDATE(J4, 36) -> 45474 | L4: =IF(ISBLANK(K4:K153), "", IF(K4:K153 < TODAY(), "Overdue", "Ok")) -> Overdue | M4: 2026-06-14T21:56:23.580Z
A5: 111.AF040 (R) | B5: Apron Feeder | C5: Clay apron feeder right gearbox | D5: Oil Analysis | E5: Mobil SHC 630 | F5: Mobil | G5: 41 | J5: 44378 | K5: =EDATE(J5, 36) -> 45474 | L5: =IF(ISBLANK(K5:K154), "", IF(K5:K154 < TODAY(), "Overdue", "Ok")) -> Overdue
A6: 111.AF060 (L) | B6: Apron Feeder | C6: Limestone Apron Feeder Left Gear Box | D6: Oil Analysis | E6: Mobil SHC 630 | F6: Mobil | G6: 41 | I6: 44378 | J6: 44954 | K6: =EDATE(J6, 36) -> 46050 | L6: =IF(ISBLANK(K6:K155), "", IF(K6:K155 < TODAY(), "Overdue", "Ok")) -> Overdue
A7: 111.AF060 (R) | B7: Apron Feeder | C7: Limestone Apron Feeder right Gear Box- BREVINI | D7: Oil Analysis | E7: Mobil SHC 630 | F7: Mobil | G7: 41 | I7: 44378 | J7: 44954 | K7: =EDATE(J7, 36) -> 46050 | L7: =IF(ISBLANK(K7:K156), "", IF(K7:K156 < TODAY(), "Overdue", "Ok")) -> Overdue
A8: 111.BC210 | B8: Belt Conveyor | C8: Belt Conveyor Gearbox - Rossi | D8: Oil Analysis | E8: Mobil SHC 632 | F8: Mobil | G8: 100 | J8: 46149 | K8: =EDATE(J8, 36) -> 47245 | L8: =IF(ISBLANK(K8:K157), "", IF(K8:K157 < TODAY(), "Overdue", "Ok")) -> Ok
A9: 111.BC330 (L1) | B9: Belt Conveyor | C9: Belt conveyor first left Gearbox | D9: Oil Analysis | E9: Mobil SHC 630 | F9: Mobil | G9: 125 | J9: 43843 | K9: =EDATE(J9, 36) -> 44939 | L9: =IF(ISBLANK(K9:K158), "", IF(K9:K158 < TODAY(), "Overdue", "Ok")) -> Overdue
A10: 111.BC330 (L2) | B10: Belt Conveyor | C10: Belt conveyor second left Gearbox | D10: Oil Analysis | E10: Mobil SHC 630 | F10: Mobil | G10: 125 | J10: 43843 | K10: =EDATE(J10, 36) -> 44939 | L10: =IF(ISBLANK(K10:K159), "", IF(K10:K159 < TODAY(), "Overdue", "Ok")) -> Overdue
A11: 111.BC330 (R1) | B11: Belt Conveyor | C11: Belt conveyor first right Gearbox | D11: Oil Analysis | E11: Mobil SHC 630 | F11: Mobil | G11: 125 | J11: 43843 | K11: =EDATE(J11, 36) -> 44939 | L11: =IF(ISBLANK(K11:K160), "", IF(K11:K160 < TODAY(), "Overdue", "Ok")) -> Overdue
A12: 111.BC330 (R2) | B12: Belt Conveyor | C12: Belt conveyor second right Gearbox | D12: Oil Analysis | E12: Mobil SHC 630 | F12: Mobil | G12: 125 | J12: 43843 | K12: =EDATE(J12, 36) -> 44939 | L12: =IF(ISBLANK(K12:K161), "", IF(K12:K161 < TODAY(), "Overdue", "Ok")) -> Overdue
A13: 111.HC100 (HY) | B13: Hammer Crusher | C13: Crusher hydraulic cylinder station | D13: Oil Analysis | E13: Mobil DTE 25 | F13: Mobil | G13: 90 | J13: 43843 | K13: =EDATE(J13, 36) -> 44939 | L13: =IF(ISBLANK(K13:K162), "", IF(K13:K162 < TODAY(), "Overdue", "Ok")) -> Overdue
A14: 111.HC100 (IR) | B14: Hammer Crusher | C14: Inlet Roller Gear Box | D14: Oil Analysis | E14: Mobil gear 600 XP 320 | F14: Mobil | G14: 50 | H14: 44615 | I14: 01.10.2023 | J14: 45558 | K14: =EDATE(J14, 36) -> 46653 | L14: =IF(ISBLANK(K14:K163), "", IF(K14:K163 < TODAY(), "Overdue", "Ok")) -> Ok
A15: 111.HC100 (RGB) | B15: Hammer Crusher | C15: Hammer Crusher Rotor Gear Box | D15: Oil Analysis | E15: Mobil gear 600 XP 320 | F15: Mobil | G15: 120 | I15: 43843 | J15: 45558 | K15: =EDATE(J15, 36) -> 46653 | L15: =IF(ISBLANK(K15:K164), "", IF(K15:K164 < TODAY(), "Overdue", "Ok")) -> Ok
A16: 123.BC100 | B16: Belt Conveyor | C16: Belt conveyor Gearbox | D16: Oil Analysis | E16: Mobil SHC 630 | F16: Mobil | G16: 125 | I16: 44503 | J16: 44749 | K16: =EDATE(J16, 36) -> 45845 | L16: =IF(ISBLANK(K16:K165), "", IF(K16:K165 < TODAY(), "Overdue", "Ok")) -> Overdue
A17: 123.BC200 | B17: Belt Conveyor | C17: Belt Conveyor Gearbox | D17: Oil Analysis | E17: Mobil SHC 630 | F17: Mobil | G17: 106 | I17: 44503 | J17: 46138 | K17: =EDATE(J17, 36) -> 47234 | L17: =IF(ISBLANK(K17:K166), "", IF(K17:K166 < TODAY(), "Overdue", "Ok")) -> Ok
A18: 131.BC100 | B18: Belt Conveyor | C18: Belt Conveyor Gearbox | D18: Oil Analysis | E18: Mobil SHC 630 | F18: Mobil | G18: 125 | H18: 44494 | I18: 44748 | J18: 45332 | K18: =EDATE(J18, 36) -> 46428 | L18: =IF(ISBLANK(K18:K167), "", IF(K18:K167 < TODAY(), "Overdue", "Ok")) -> Ok
A19: 131.BC500 (M01) | B19: Belt Conveyor | C19: Belt Conveyor Gearbox | D19: Oil Analysis | E19: Mobil SHC 630 | F19: Mobil | G19: 125 | J19: 43313 | K19: =EDATE(J19, 36) -> 44409 | L19: =IF(ISBLANK(K19:K168), "", IF(K19:K168 < TODAY(), "Overdue", "Ok")) -> Overdue
A20: 131.BC500 (M02) | B20: Belt Conveyor | C20: Belt Conveyor Gearbox | D20: Oil Analysis | E20: Mobil SHC 630 | F20: Mobil | G20: 125 | J20: 43313 | K20: =EDATE(J20, 36) -> 44409 | L20: =IF(ISBLANK(K20:K169), "", IF(K20:K169 < TODAY(), "Overdue", "Ok")) -> Overdue
A21: 131.RE300 | B21: Reclaimer | C21: Take up unit Tank for Scraper Chain | D21: 1.5 Y | E21: Mobil gear 600 XP 320 | F21: Mobil | G21: 70 | H21: 43983 | I21: 44699 | J21: 46134 | K21: =EDATE(J31, 18) -> 46695 | L21: =IF(ISBLANK(K21:K170), "", IF(K21:K170 < TODAY(), "Overdue", "Ok")) -> Ok
A22: 131.RE300.M11 | B22: Reclaimer | C22: Reclaimer Chain Scraper gearbox | D22: Oil Analysis | E22: Mobil gear 600 XP 320 | F22: Mobil | G22: 125 | H22: 44497 | I22: 44692 | J22: 46134 | K22: =EDATE(J22, 36) -> 47230 | L22: =IF(ISBLANK(K22:K171), "", IF(K22:K171 < TODAY(), "Overdue", "Ok")) -> Ok
A23: 131.RE300.M12 | B23: Reclaimer | C23: Reclaimer Chain Scraper gearbox | D23: Oil Analysis | E23: Mobil gear 600 XP 320 | F23: Mobil | G23: 125 | H23: 44497 | I23: 44692 | J23: 46134 | K23: =EDATE(J23, 36) -> 47230 | L23: =IF(ISBLANK(K23:K172), "", IF(K23:K172 < TODAY(), "Overdue", "Ok")) -> Ok
A24: 131.ST200 (HY) | B24: Stacker | C24: Jib arm Hydraulic Pump Station | D24: Oil Analysis | E24: Mobil DTE 25 | F24: Mobil | G24: 100 | J24: 46133 | K24: =EDATE(J24, 36) -> 47229 | L24: =IF(ISBLANK(K24:K173), "", IF(K24:K173 < TODAY(), "Overdue", "Ok")) -> Ok
